Workbook

Sheet Paso a paso
A1: Control de costo vs venta vs ejecutado — Colegio Técnico Nacional
A2: Método paso a paso con 4 ítems de ejemplo. Guaraníes (Gs). Leé las hojas en este orden.
A4: Paso | B4: Hoja | C4: Qué se hace
A5: 1 | B5: Coeficiente | C5: Descubrir con qué coeficiente se armó el precio: se divide el precio unitario de la planilla por el costo que está en las columnas ocultas (MO + materiales). Da 1,3454 en los 36 ítems que tienen el detalle.
A6: 2 | B6: Insumos | C6: Lista de precios de cada material, mano de obra y equipo, y su TIPO: DIRECTO (se asigna al ítem con el remito o certificado), COMÚN (va al stock de la obra y se reparte por consumo teórico) o TIEMPO (equipos, se reparte por uso).
A7: 3 | B7: ACU | C7: Análisis de costo unitario (la mano de obra sale de la Lista MO contratistas) de cada ítem: consumo por unidad × precio del insumo. Se compara con el costo que usó la oferta. Si el ACU da más, el ítem ya pierde margen antes de empezar (ver viga).
A8: 4 | B8: Presupuesto control | C8: Por ítem: precio de venta, costo meta (ACU), margen previsto. Todo sin IVA para comparar peras con peras (los costos de la planilla son sin IVA).
A9: 5 | B9: Medición mes | C9: Cantidad planificada (cronograma) y ejecutada (medición de obra) del mes. Es la MISMA medición que respalda el certificado al cliente.
A10: 6 | B10: Materiales | C10: Consumo teórico = ejecutado × consumo del ACU. Para los insumos COMUNES se hace inventario: real = stock inicial + compras − stock final. El desvío se valoriza y se alerta si pasa la tolerancia.
A11: 7 | B11: Costo real mes | C11: Costo real por ítem: MO certificada al subcontratista + materiales DIRECTOS según remitos + materiales COMUNES según consumo teórico + equipos. El desvío de inventario NO va a un ítem: va a 'pérdidas de material'.
A12: 8 | B12: Resumen | C12: Venta certificada vs costo real vs valor ganado. Índice de costo (IC = VG/CR), índice de plazo (IP = VG/VP), costo proyectado al final y resultado de la obra.
A15: Convención de colores
A16: Columna 'Fuente / nota' en Insumos: indica qué precios son supuestos a reemplazar por datos reales.
A17: Las alertas se muestran en rojo.
A21: Fuentes: planilla '1.4-1.5-1.6-2.2-2.3_Plan_de_trabajo_CTN.xlsx' (precios, cantidades y costos de las columnas ocultas K–O de la hoja 16)-B3-ELECT). Mano de obra: lista real de precios a contratistas. Precios de materiales, consumos del hormigón y datos del mes son SUPUESTOS de ejemplo.

Sheet 1 Coeficiente
A1: Paso 1 · Coeficiente de pase real de la oferta
A2: Datos reales de la hoja 16)-B3-ELECT (columnas ocultas L = Mano de obra, M = Materiales, N = Costo unitario sin IVA).
A4: Ítem | B4: Descripción | C4: Un. | D4: PU planilla (Gs, con IVA) | E4: MO (Gs) | F4: Materiales (Gs) | G4: Costo unitario sin IVA (Gs) | H4: Coeficiente PU / Costo
A5: 1.2.3 | B5: Demolición de mamposterías sin recuperación | C5: m2 | D5: 29060.619 | E5: 21600 | F5: 0 | G5: =E5+F5 -> 21600 | H5: =IFERROR(D5/G5,0) -> 1.345399
A6: 3.1 | B6: Mampostería de nivelación de 0.30m | C6: m2 | D6: 230063.24 | E6: 52000 | F6: 119000 | G6: =E6+F6 -> 171000 | H6: =IFERROR(D6/G6,0) -> 1.345399
A7: 3.3 | B7: Mampostería de elevación ladrillo semiprensado visto ambas caras 0.15m | C7: m2 | D7: 228717.84 | E7: 70000 | F7: 100000 | G7: =E7+F7 -> 170000 | H7: =IFERROR(D7/G7,0) -> 1.345399
A8: 3.4 | B8: Mampostería de elevación ladrillo común 0.15m | C8: m2 | D8: 127090.43 | E8: 35000 | F8: 59463 | G8: =E8+F8 -> 94463 | H8: =IFERROR(D8/G8,0) -> 1.345399
A9: 3.5 | B9: Mampostería de elevación ladrillo común 0.30m | C9: m2 | D9: 234099.43 | E9: 55000 | F9: 119000 | G9: =E9+F9 -> 174000 | H9: =IFERROR(D9/G9,0) -> 1.345399
A10: 2.1 | B10: Aislación horizontal pintura asfáltica 0.15m | C10: ml | D10: 32721.45 | E10: 18700 | F10: 5621 | G10: =E10+F10 -> 24321 | H10: =IFERROR(D10/G10,0) -> 1.345399
A11: 4.1 | B11: Azotada impermeable | C11: m2 | D11: 16144.788 | E11: 7000 | F11: 5000 | G11: =E11+F11 -> 12000 | H11: =IFERROR(D11/G11,0) -> 1.345399
G12: Coeficiente efectivo | H12: =AVERAGE(H5:H11) -> 1.345399
A14: Descomposición del coeficiente
A15: Concepto | B15: Valor | C15: Cómo se obtiene
A16: Coef. declarado (celda L2 de la planilla) | B16: 1.25 | C16: Dato escrito en la planilla
A17: IVA | B17: 1.1 | C17: 10 % Paraguay
A18: Coef. declarado con IVA | B18: =B16*B17 -> 1.375 | C18: 1,25 × 1,10
A19: Coef. efectivo medido | B19: ='1 Coeficiente'!$H$12 -> 1.345399 | C19: Promedio de la tabla de arriba
A20: Ajuste aplicado sobre el precio | B20: =B19/B18 -> 0.97847203 | C20: Efectivo ÷ declarado. <1 = rebaja general de precios
A21: Rebaja general implícita | B21: =1-B20 -> 0.02152797 | C21: Probable ajuste para llegar al monto de contrato
A22: Coef. de pase SIN IVA (K) | B22: =B19/B17 -> 1.22309 | C22: Precio sin IVA ÷ costo directo
A23: Margen sobre el costo directo | B23: =B22-1 -> 0.22309004 | C23: Gastos generales + imprevistos + beneficio sobre el costo
A24: Margen sobre la venta sin IVA | B24: =1-1/B22 -> 0.1823987 | C24: Qué parte de cada Gs facturado (sin IVA) no es costo directo
A26: Conclusión: todos los precios = costo directo × 1,3454 (con IVA). Es el 1,375 declarado (1,25 × IVA) con una rebaja de ≈2,15 %. En el resto del presupuesto el costo directo se obtiene como PU ÷ 1,3454; da costos redondos (ej. losa 2.634.000 Gs/m³, viga 2.930.000, pilar 7.400.000), lo que confirma el método.

Sheet Lista MO contratistas
A1: Lista de precios de mano de obra a contratistas
A2: Fuente: PRECIO_MANO_DE_OBRA.pdf (provista por la empresa). Precios por unidad, en Gs.
A4: Sector | B4: Ítem | C4: Descripción | D4: Un. | E4: Precio MO (Gs) | F4: Usado en ACU
A5: Planta baja | B5: 1.1 | C5: Limpieza de Terreno. Retiro de escombros | D5: m2 | E5: 8000
A6: Planta baja | B6: 1.2 | C6: Replanteo y Marcación | D6: m2 | E6: 3500
A7: Planta baja | B7: 1.3 | C7: Aislación horizontal con pintura asfáltica de 0.15m. | D7: ml | E7: 18000
A8: Planta baja | B8: 1.4 | C8: Aislación horizontal con pintura asfáltica de 0,30 m | D8: ml | E8: 21000
A9: Planta baja | B9: 1.5 | C9: Aislación horizontal con pintura asfáltica de 0,45 m | D9: ml | E9: 24000
A10: Planta baja | B10: 1.6 | C10: Aislación horizontal de baños con Aditivo Hidrófugo Betocem | D10: m2 | E10: 34000
A11: Planta baja | B11: 1.7 | C11: Mampostería de nivelación de 0.30m. | D11: m2 | E11: 41000
A12: Planta baja | B12: 1.8 | C12: Doble Mampostería de elevación de 0,15 de ladrillo visto ambas caras (0,30) | D12: m2 | E12: 100000
A13: Planta baja | B13: 1.9 | C13: Mampostería de elevación de ladrillo común de 0.15m. | D13: m2 | E13: 31000 | F13: Insumo MOC
A14: Planta baja | B14: 1.10 | C14: Envarillado de mampostería de 6mm a media altura | D14: ml | E14: 10000
A15: Planta baja | B15: 1.11 | C15: Envarillado doble de mampostería de 8mm en dinteles de aberturas | D15: ml | E15: 25000
A16: Planta baja | B16: 1.12 | C16: Azotada impermeable | D16: m2 | E16: 10000
A17: Planta baja | B17: 1.13 | C17: Revoque interior con hidrófugo para revestimiento en baños | D17: m2 | E17: 25000
A18: Planta baja | B18: 1.14 | C18: Revoque de mochetas | D18: ml | E18: 30000
A19: Planta baja | B19: 1.15 | C19: Contrapiso de cascotes cerámicos de 10cm. Sobre terreno natural. Para baños | D19: m2 | E19: 20000
A20: Planta baja | B20: 1.16 | C20: Carpeta de nivelación Esp.= 0,03m | D20: m2 | E20: 25000
A21: Planta baja | B21: 1.17 | C21: Piso de granito reconstituido 30x30 de color gris | D21: m2 | E21: 38000
A22: Planta baja | B22: 1.18 | C22: Colocacion de piso paver, incluye colchon de triturada sexta | D22: m2 | E22: 35000
A23: Planta baja | B23: 1.19 | C23: Zócalo de granito reconstituido de color gris (h=10cm) | D23: ml | E23: 18000
A24: Planta baja | B24: 1.20 | C24: Revestimiento Cerámico de azulejos tipo piso/pared en muro 20x30cm | D24: m2 | E24: 40000
A25: Planta baja | B25: 1.21 | C25: Excavación para fundación | D25: m3 | E25: 60000
A26: Planta baja | B26: 1.22 | C26: Cimiento de piedra bruta colocada | D26: m3 | E26: 110000
A27: Planta baja | B27: 1.23 | C27: Viga de H°A° | D27: m3 | E27: 800000 | F27: Insumo MOW
A28: Planta baja | B28: 1.24 | C28: Mampostería de elevación de ladrillo semiprensado visto una cara de 0,15 m | D28: m2 | E28: 50000 | F28: Insumo MOV
A29: Planta baja | B29: 1.25 | C29: Mampostería de elevación de ladrillo común 0,30 m | D29: m2 | E29: 52000
A30: Planta baja | B30: 1.26 | C30: Mampostería de elevación de ladrillo común 0,45 m | D30: m2 | E30: 83000
A31: Planta baja | B31: 1.27 | C31: Viga cadena superior | D31: m3 | E31: 850000
A32: Planta baja | B32: 1.28 | C32: Pilar de H°A° | D32: m3 | E32: 800000
A33: Planta baja | B33: 1.29 | C33: Losa de H°A° | D33: m3 | E33: 850000 | F33: Insumo MOL
A34: Planta baja | B34: 1.30 | C34: Zapata de H°A° | D34: m3 | E34: 750000
A35: Planta baja | B35: 1.31 | C35: Viga de H°A° | D35: m3 | E35: 800000
A36: Planta baja | B36: 1.32 | C36: Pintura exterior de paredes al latex nacional | D36: m2 | E36: 23000
A37: Planta baja | B37: 1.33 | C37: Pintura de techo al latex nacional | D37: m2 | E37: 23000
A38: Planta baja | B38: 1.34 | C38: Pintura interior de paredes al latex nacional, incluye enduido | D38: m2 | E38: 30000
A39: Planta baja | B39: 1.35 | C39: Pintura interior de cielorraso/losa al latex nacional, incluye enduido | D39: m2 | E39: 32000
A40: Planta baja | B40: 1.36 | C40: Pintura de aberturas de madera u marcos al barnis natural | D40: m2 | E40: 22000
A41: Planta baja | B41: 1.37 | C41: Pintura de aberturas metalicas | D41: m2 | E41: 25000
...

Sheet 2 Insumos
A1: Paso 2 · Insumos, precios y tipo de imputación
A2: Precios sin IVA. Los marcados con fondo amarillo son supuestos: reemplazar por cotizaciones reales.
A4: Código | B4: Insumo | C4: Un. | D4: Precio (Gs, sin IVA) | E4: Tipo | F4: Tolerancia desvío | G4: Fuente / nota
A5: LC | B5: Ladrillo común | C5: un | D5: 700 | E5: COMÚN | F5: 0.05 | G5: Supuesto
A6: LV | B6: Ladrillo semiprensado visto | C6: un | D6: 1300 | E6: COMÚN | F6: 0.04 | G6: Supuesto
A7: CEM | B7: Cemento portland (bolsa 50 kg) | C7: bolsa | D7: 58000 | E7: COMÚN | F7: 0.05 | G7: Supuesto
A8: CAL | B8: Cal hidratada | C8: kg | D8: 1200 | E8: COMÚN | F8: 0.05 | G8: Supuesto
A9: AR | B9: Arena lavada | C9: m3 | D9: 150000 | E9: COMÚN | F9: 0.1 | G9: Supuesto
A10: MM | B10: Materiales menores (hidrófugo, junta tomada) | C10: m2 | D10: 5000 | E10: COMÚN | F10: - | G10: Supuesto; sin inventario
A11: HE | B11: Hormigón elaborado H21 (fck 210) | C11: m3 | D11: 900000 | E11: DIRECTO | F11: 0.03 | G11: Supuesto; se controla por remito
A12: AC | B12: Acero CA-50 | C12: kg | D12: 9500 | E12: DIRECTO | F12: 0.03 | G12: Precio usado en la planilla (envarillado: 9.500 Gs/kg)
A13: AL | B13: Alambre de atar | C13: kg | D13: 15000 | E13: COMÚN | F13: 0.1 | G13: Supuesto
A14: EN | B14: Encofrado fenólico + puntales (amortizado) | C14: m2 | D14: 35000 | E14: TIEMPO | F14: - | G14: Supuesto
A15: BV | B15: Bombeo y vibrado | C15: m3 | D15: 55000 | E15: TIEMPO | F15: - | G15: Supuesto
A16: MOV | B16: MO mampostería visto 0,15 (subcontrato) | C16: m2 | D16: ='Lista MO contratistas'!E28 -> 50000 | E16: DIRECTO | F16: - | G16: Lista MO contratistas, ítem 1.24 (visto una cara 0,15, planta baja)
A17: MOC | B17: MO mampostería común 0,15 (subcontrato) | C17: m2 | D17: ='Lista MO contratistas'!E13 -> 31000 | E17: DIRECTO | F17: - | G17: Lista MO contratistas, ítem 1.9 (planta baja)
A18: MOL | B18: MO estructura losa (subcontrato) | C18: m3 | D18: ='Lista MO contratistas'!E33 -> 850000 | E18: DIRECTO | F18: - | G18: Lista MO contratistas, ítem 1.29 Losa de H°A°
A19: MOW | B19: MO estructura viga (subcontrato) | C19: m3 | D19: ='Lista MO contratistas'!E27 -> 800000 | E19: DIRECTO | F19: - | G19: Lista MO contratistas, ítem 1.23 Viga de H°A°

Sheet 3 ACU
A1: Paso 3 · Análisis de costo unitario (ACU)
A2: Consumo por unidad × precio del insumo. Se compara con el costo que usó la oferta (PU ÷ coeficiente efectivo).
A4: ÍTEM 3.3 (B3) — Mampostería de elevación ladrillo semiprensado visto ambas caras 0,15 m [m2]
A5: Código | B5: Insumo | C5: Un. | D5: Consumo por m2 | E5: Precio unit. (Gs) | F5: Parcial (Gs/m2) | G5: Grupo
A6: LV | B6: Ladrillo semiprensado visto | C6: un | D6: 58 | E6: ='2 Insumos'!$D$6 -> 1300 | F6: =D6*E6 -> 75400 | G6: MAT
A7: CEM | B7: Cemento portland (bolsa 50 kg) | C7: bolsa | D7: 0.12 | E7: ='2 Insumos'!$D$7 -> 58000 | F7: =D7*E7 -> 6960 | G7: MAT
A8: CAL | B8: Cal hidratada | C8: kg | D8: 6 | E8: ='2 Insumos'!$D$8 -> 1200 | F8: =D8*E8 -> 7200 | G8: MAT
A9: AR | B9: Arena lavada | C9: m3 | D9: 0.035 | E9: ='2 Insumos'!$D$9 -> 150000 | F9: =D9*E9 -> 5250 | G9: MAT
A10: MM | B10: Materiales menores (hidrófugo, junta tomada) | C10: m2 | D10: 1 | E10: ='2 Insumos'!$D$10 -> 5000 | F10: =D10*E10 -> 5000 | G10: MAT
A11: MOV | B11: MO mampostería visto 0,15 (subcontrato) | C11: m2 | D11: 1 | E11: ='2 Insumos'!$D$16 -> 50000 | F11: =D11*E11 -> 50000 | G11: MO
E12: Materiales | F12: =SUMIF(G6:G11,"MAT",F6:F11) -> 99810
E13: Mano de obra | F13: =SUMIF(G6:G11,"MO",F6:F11) -> 50000
E14: Equipos | F14: =SUMIF(G6:G11,"EQ",F6:F11) -> 0
E15: COSTO DIRECTO ACU | F15: =SUM(F12:F14) -> 149810
E16: PU de contrato (con IVA) | F16: 228717.84
E17: Costo usado en la oferta | F17: =F16/'1 Coeficiente'!$H$12 -> 170000
E18: Diferencia ACU − oferta | F18: =F15-F17 -> -20190
E19: Venta sin IVA | F19: =F16/'1 Coeficiente'!$B$17 -> 207925.31
E20: Margen previsto s/ venta sin IVA | F20: =1-F15/F19 -> 0.27950088
E21: Estado | F21: =IF(F18>0,"ACU supera la oferta: margen menor al cotizado","OK: ACU dentro del costo cotizado") -> OK: ACU dentro del costo cotizado
A23: ÍTEM 3.4 (B3) — Mampostería de elevación ladrillo común 0,15 m [m2]
A24: Código | B24: Insumo | C24: Un. | D24: Consumo por m2 | E24: Precio unit. (Gs) | F24: Parcial (Gs/m2) | G24: Grupo
A25: LC | B25: Ladrillo común | C25: un | D25: 60 | E25: ='2 Insumos'!$D$5 -> 700 | F25: =D25*E25 -> 42000 | G25: MAT
A26: CEM | B26: Cemento portland (bolsa 50 kg) | C26: bolsa | D26: 0.1 | E26: ='2 Insumos'!$D$7 -> 58000 | F26: =D26*E26 -> 5800 | G26: MAT
A27: CAL | B27: Cal hidratada | C27: kg | D27: 6 | E27: ='2 Insumos'!$D$8 -> 1200 | F27: =D27*E27 -> 7200 | G27: MAT
A28: AR | B28: Arena lavada | C28: m3 | D28: 0.035 | E28: ='2 Insumos'!$D$9 -> 150000 | F28: =D28*E28 -> 5250 | G28: MAT
A29: MOC | B29: MO mampostería común 0,15 (subcontrato) | C29: m2 | D29: 1 | E29: ='2 Insumos'!$D$17 -> 31000 | F29: =D29*E29 -> 31000 | G29: MO
E30: Materiales | F30: =SUMIF(G25:G29,"MAT",F25:F29) -> 60250
E31: Mano de obra | F31: =SUMIF(G25:G29,"MO",F25:F29) -> 31000
E32: Equipos | F32: =SUMIF(G25:G29,"EQ",F25:F29) -> 0
E33: COSTO DIRECTO ACU | F33: =SUM(F30:F32) -> 91250
E34: PU de contrato (con IVA) | F34: 127090.43
E35: Costo usado en la oferta | F35: =F34/'1 Coeficiente'!$H$12 -> 94463
E36: Diferencia ACU − oferta | F36: =F33-F35 -> -3213
E37: Venta sin IVA | F37: =F34/'1 Coeficiente'!$B$17 -> 115536.75
E38: Margen previsto s/ venta sin IVA | F38: =1-F33/F37 -> 0.21020804
E39: Estado | F39: =IF(F36>0,"ACU supera la oferta: margen menor al cotizado","OK: ACU dentro del costo cotizado") -> OK: ACU dentro del costo cotizado
A41: ÍTEM 3.2 (B6 +4,20) — Ejecución de losas de HºAº fck 210 kg/cm² [m3]
A42: Código | B42: Insumo | C42: Un. | D42: Consumo por m3 | E42: Precio unit. (Gs) | F42: Parcial (Gs/m3) | G42: Grupo
A43: HE | B43: Hormigón elaborado H21 (fck 210) | C43: m3 | D43: 1.05 | E43: ='2 Insumos'!$D$11 -> 900000 | F43: =D43*E43 -> 945000 | G43: MAT
...

Sheet 4 Presupuesto control
A1: Paso 4 · Presupuesto de control (venta vs costo meta)
A2: Montos sin IVA. Costo meta = ACU. El margen del contrato es lo que la obra DEBERÍA ganar si se cumple el ACU.
A4: Ítem | B4: Descripción | C4: Un. | D4: Cantidad contrato | E4: PU venta con IVA | F4: PU venta sin IVA | G4: Costo meta unit. (ACU) | H4: de él: materiales | I4: de él: mano de obra | J4: de él: equipos | K4: Venta total sin IVA | L4: Costo meta total | M4: Margen previsto (Gs) | N4: Margen %
A5: 3.3 (B3) | B5: Mampostería de elevación ladrillo semiprensado visto ambas caras 0,15 m | C5: m2 | D5: 51.704 | E5: ='3 ACU'!F16 -> 228717.84 | F5: =E5/'1 Coeficiente'!$B$17 -> 207925.31 | G5: ='3 ACU'!F15 -> 149810 | H5: ='3 ACU'!F12 -> 99810 | I5: ='3 ACU'!F13 -> 50000 | J5: ='3 ACU'!F14 -> 0 | K5: =D5*F5 -> 10750570 | L5: =D5*G5 -> 7745776.2 | M5: =K5-L5 -> 3004793.8 | N5: =IFERROR(M5/K5,0) -> 0.27950088
A6: 3.4 (B3) | B6: Mampostería de elevación ladrillo común 0,15 m | C6: m2 | D6: 173.409 | E6: ='3 ACU'!F34 -> 127090.43 | F6: =E6/'1 Coeficiente'!$B$17 -> 115536.75 | G6: ='3 ACU'!F33 -> 91250 | H6: ='3 ACU'!F30 -> 60250 | I6: ='3 ACU'!F31 -> 31000 | J6: ='3 ACU'!F32 -> 0 | K6: =D6*F6 -> 20035113 | L6: =D6*G6 -> 15823571 | M6: =K6-L6 -> 4211541.8 | N6: =IFERROR(M6/K6,0) -> 0.21020804
A7: 3.2 (B6 +4,20) | B7: Ejecución de losas de HºAº fck 210 kg/cm² | C7: m3 | D7: 97.5 | E7: ='3 ACU'!F53 -> 3543781.1 | F7: =E7/'1 Coeficiente'!$B$17 -> 3221619.2 | G7: ='3 ACU'!F52 -> 3102500 | H7: ='3 ACU'!F49 -> 1917500 | I7: ='3 ACU'!F50 -> 850000 | J7: ='3 ACU'!F51 -> 335000 | K7: =D7*F7 -> 3.1410787e+08 | L7: =D7*G7 -> 302493750 | M7: =K7-L7 -> 11614118 | N7: =IFERROR(M7/K7,0) -> 0.036974935
A8: 3.3 (B6 +4,20) | B8: Ejecución de vigas de HºAº fck 210 kg/cm² | C8: m3 | D8: 132.4 | E8: ='3 ACU'!F72 -> 3942019.2 | F8: =E8/'1 Coeficiente'!$B$17 -> 3583653.8 | G8: ='3 ACU'!F71 -> 3390000 | H8: ='3 ACU'!F68 -> 2115000 | I8: ='3 ACU'!F69 -> 800000 | J8: ='3 ACU'!F70 -> 475000 | K8: =D8*F8 -> 4.7447576e+08 | L8: =D8*G8 -> 448836000 | M8: =K8-L8 -> 25639765 | N8: =IFERROR(M8/K8,0) -> 0.054038091
B9: TOTAL | K9: =SUM(K5:K8) -> 8.1936932e+08 | L9: =SUM(L5:L8) -> 7.748991e+08 | M9: =SUM(M5:M8) -> 44470218 | N9: =IFERROR(M9/K9,0) -> 0.054273717

Sheet 5 Medición mes
A1: Paso 5 · Medición del mes 3 (planificado vs ejecutado)
A2: Cantidades del mes. Planificado = cronograma; ejecutado = medición de obra (la misma que va al certificado al cliente). Valores de ejemplo.
A4: Ítem | B4: Descripción | C4: Un. | D4: Cantidad contrato | E4: Acum. anterior | F4: Planificado mes | G4: Ejecutado mes | H4: Acum. actual | I4: % avance acumulado | J4: Cumplimiento del mes
A5: 3.3 (B3) | B5: Mampostería de elevación ladrillo semiprensado visto ambas caras 0,15 m | C5: m2 | D5: ='4 Presupuesto control'!D5 -> 51.704 | E5: 10 | F5: 20 | G5: 18 | H5: =E5+G5 -> 28 | I5: =IFERROR(H5/D5,0) -> 0.54154417 | J5: =IFERROR(G5/F5,0) -> 0.9
A6: 3.4 (B3) | B6: Mampostería de elevación ladrillo común 0,15 m | C6: m2 | D6: ='4 Presupuesto control'!D6 -> 173.409 | E6: 40 | F6: 80 | G6: 95 | H6: =E6+G6 -> 135 | I6: =IFERROR(H6/D6,0) -> 0.77850631 | J6: =IFERROR(G6/F6,0) -> 1.1875
A7: 3.2 (B6 +4,20) | B7: Ejecución de losas de HºAº fck 210 kg/cm² | C7: m3 | D7: ='4 Presupuesto control'!D7 -> 97.5 | E7: 0 | F7: 48.75 | G7: 40 | H7: =E7+G7 -> 40 | I7: =IFERROR(H7/D7,0) -> 0.41025641 | J7: =IFERROR(G7/F7,0) -> 0.82051282
A8: 3.3 (B6 +4,20) | B8: Ejecución de vigas de HºAº fck 210 kg/cm² | C8: m3 | D8: ='4 Presupuesto control'!D8 -> 132.4 | E8: 0 | F8: 66.2 | G8: 58 | H8: =E8+G8 -> 58 | I8: =IFERROR(H8/D8,0) -> 0.43806647 | J8: =IFERROR(G8/F8,0) -> 0.87613293

Sheet 6 Materiales
A1: Paso 6 · Consumo teórico vs real de materiales
A2: Teórico = ejecutado × consumo del ACU. COMUNES: real por inventario. DIRECTOS: real por remitos/planilla de doblado del ítem.
A4: Código | B4: Insumo | C4: Un. | D4: Tipo | E4: Teórico ítem 3.3 (B3) | F4: Teórico ítem 3.4 (B3) | G4: Teórico ítem 3.2 (B6 +4,20) | H4: Teórico ítem 3.3 (B6 +4,20) | I4: Teórico total
A5: LC | B5: Ladrillo común | C5: un | D5: COMÚN | E5: 0 | F5: ='5 Medición mes'!$G$6*'3 ACU'!D25 -> 5700 | G5: 0 | H5: 0 | I5: =SUM(E5:H5) -> 5700
A6: LV | B6: Ladrillo semiprensado visto | C6: un | D6: COMÚN | E6: ='5 Medición mes'!$G$5*'3 ACU'!D6 -> 1044 | F6: 0 | G6: 0 | H6: 0 | I6: =SUM(E6:H6) -> 1044
A7: CEM | B7: Cemento portland (bolsa 50 kg) | C7: bolsa | D7: COMÚN | E7: ='5 Medición mes'!$G$5*'3 ACU'!D7 -> 2.16 | F7: ='5 Medición mes'!$G$6*'3 ACU'!D26 -> 9.5 | G7: 0 | H7: 0 | I7: =SUM(E7:H7) -> 11.66
A8: CAL | B8: Cal hidratada | C8: kg | D8: COMÚN | E8: ='5 Medición mes'!$G$5*'3 ACU'!D8 -> 108 | F8: ='5 Medición mes'!$G$6*'3 ACU'!D27 -> 570 | G8: 0 | H8: 0 | I8: =SUM(E8:H8) -> 678
A9: AR | B9: Arena lavada | C9: m3 | D9: COMÚN | E9: ='5 Medición mes'!$G$5*'3 ACU'!D9 -> 0.63 | F9: ='5 Medición mes'!$G$6*'3 ACU'!D28 -> 3.325 | G9: 0 | H9: 0 | I9: =SUM(E9:H9) -> 3.955
A10: MM | B10: Materiales menores (hidrófugo, junta tomada) | C10: m2 | D10: COMÚN | E10: ='5 Medición mes'!$G$5*'3 ACU'!D10 -> 18 | F10: 0 | G10: 0 | H10: 0 | I10: =SUM(E10:H10) -> 18
A11: HE | B11: Hormigón elaborado H21 (fck 210) | C11: m3 | D11: DIRECTO | E11: 0 | F11: 0 | G11: ='5 Medición mes'!$G$7*'3 ACU'!D43 -> 42 | H11: ='5 Medición mes'!$G$8*'3 ACU'!D62 -> 60.9 | I11: =SUM(E11:H11) -> 102.9
A12: AC | B12: Acero CA-50 | C12: kg | D12: DIRECTO | E12: 0 | F12: 0 | G12: ='5 Medición mes'!$G$7*'3 ACU'!D44 -> 4000 | H12: ='5 Medición mes'!$G$8*'3 ACU'!D63 -> 6960 | I12: =SUM(E12:H12) -> 10960
A13: AL | B13: Alambre de atar | C13: kg | D13: COMÚN | E13: 0 | F13: 0 | G13: ='5 Medición mes'!$G$7*'3 ACU'!D45 -> 60 | H13: ='5 Medición mes'!$G$8*'3 ACU'!D64 -> 116 | I13: =SUM(E13:H13) -> 176
A14: EN | B14: Encofrado fenólico + puntales (amortizado) | C14: m2 | D14: TIEMPO | E14: 0 | F14: 0 | G14: ='5 Medición mes'!$G$7*'3 ACU'!D46 -> 320 | H14: ='5 Medición mes'!$G$8*'3 ACU'!D65 -> 696 | I14: =SUM(E14:H14) -> 1016
A15: BV | B15: Bombeo y vibrado | C15: m3 | D15: TIEMPO | E15: 0 | F15: 0 | G15: ='5 Medición mes'!$G$7*'3 ACU'!D47 -> 40 | H15: ='5 Medición mes'!$G$8*'3 ACU'!D66 -> 58 | I15: =SUM(E15:H15) -> 98
A17: B) Insumos COMUNES: inventario del mes
A18: Código | B18: Insumo | C18: Un. | D18: Stock inicial | E18: Compras del mes | F18: Stock final (conteo) | G18: Consumo real | H18: Consumo teórico | I18: Desvío (cant.) | J18: Desvío % | K18: Tolerancia | L18: Desvío valorizado (Gs) | M18: Estado
A19: LC | B19: Ladrillo común | C19: un | D19: 2000 | E19: 5000 | F19: 1000 | G19: =D19+E19-F19 -> 6000 | H19: =I5 -> 5700 | I19: =G19-H19 -> 300 | J19: =IFERROR(I19/H19,0) -> 0.052631579 | K19: ='2 Insumos'!F5 -> 0.05 | L19: =I19*'2 Insumos'!$D$5 -> 210000 | M19: =IF(J19>K19,"ALERTA",IF(J19<-K19,"Revisar (consumo bajo)","OK")) -> ALERTA
A20: LV | B20: Ladrillo semiprensado visto | C20: un | D20: 0 | E20: 1200 | F20: 120 | G20: =D20+E20-F20 -> 1080 | H20: =I6 -> 1044 | I20: =G20-H20 -> 36 | J20: =IFERROR(I20/H20,0) -> 0.034482759 | K20: ='2 Insumos'!F6 -> 0.04 | L20: =I20*'2 Insumos'!$D$6 -> 46800 | M20: =IF(J20>K20,"ALERTA",IF(J20<-K20,"Revisar (consumo bajo)","OK")) -> OK
A21: CEM | B21: Cemento portland (bolsa 50 kg) | C21: bolsa | D21: 5 | E21: 12 | F21: 4 | G21: =D21+E21-F21 -> 13 | H21: =I7 -> 11.66 | I21: =G21-H21 -> 1.34 | J21: =IFERROR(I21/H21,0) -> 0.11492281 | K21: ='2 Insumos'!F7 -> 0.05 | L21: =I21*'2 Insumos'!$D$7 -> 77720 | M21: =IF(J21>K21,"ALERTA",IF(J21<-K21,"Revisar (consumo bajo)","OK")) -> ALERTA
A22: CAL | B22: Cal hidratada | C22: kg | D22: 100 | E22: 700 | F22: 75 | G22: =D22+E22-F22 -> 725 | H22: =I8 -> 678 | I22: =G22-H22 -> 47 | J22: =IFERROR(I22/H22,0) -> 0.069321534 | K22: ='2 Insumos'!F8 -> 0.05 | L22: =I22*'2 Insumos'!$D$8 -> 56400 | M22: =IF(J22>K22,"ALERTA",IF(J22<-K22,"Revisar (consumo bajo)","OK")) -> ALERTA
A23: AR | B23: Arena lavada | C23: m3 | D23: 1 | E23: 4 | F23: 0.8 | G23: =D23+E23-F23 -> 4.2 | H23: =I9 -> 3.955 | I23: =G23-H23 -> 0.245 | J23: =IFERROR(I23/H23,0) -> 0.061946903 | K23: ='2 Insumos'!F9 -> 0.1 | L23: =I23*'2 Insumos'!$D$9 -> 36750 | M23: =IF(J23>K23,"ALERTA",IF(J23<-K23,"Revisar (consumo bajo)","OK")) -> OK
A24: AL | B24: Alambre de atar | C24: kg | D24: 20 | E24: 180 | F24: 15 | G24: =D24+E24-F24 -> 185 | H24: =I13 -> 176 | I24: =G24-H24 -> 9 | J24: =IFERROR(I24/H24,0) -> 0.051136364 | K24: ='2 Insumos'!F13 -> 0.1 | L24: =I24*'2 Insumos'!$D$13 -> 135000 | M24: =IF(J24>K24,"ALERTA",IF(J24<-K24,"Revisar (consumo bajo)","OK")) -> OK
K25: Pérdida total | L25: =SUM(L19:L24) -> 562670
A27: C) Insumos DIRECTOS: remitos y planillas de doblado por ítem
A28: Ítem | B28: Insumo | C28: Un. | D28: Real según remitos | E28: Teórico | F28: Desvío (cant.) | G28: Desvío % | H28: Precio real (Gs) | I28: Costo real (Gs) | J28: Tolerancia | K28: Estado
A29: 3.2 (B6 +4,20) | B29: Hormigón elaborado H21 (fck 210) | C29: m3 | D29: 43.5 | E29: =G11 -> 42 | F29: =D29-E29 -> 1.5 | G29: =IFERROR(F29/E29,0) -> 0.035714286 | H29: 915000 | I29: =D29*H29 -> 39802500 | J29: ='2 Insumos'!F11 -> 0.03 | K29: =IF(ABS(G29)>J29,"ALERTA","OK") -> ALERTA
A30: 3.2 (B6 +4,20) | B30: Acero CA-50 | C30: kg | D30: 3900 | E30: =G12 -> 4000 | F30: =D30-E30 -> -100 | G30: =IFERROR(F30/E30,0) -> -0.025 | H30: 9500 | I30: =D30*H30 -> 37050000 | J30: ='2 Insumos'!F12 -> 0.03 | K30: =IF(ABS(G30)>J30,"ALERTA","OK") -> OK
A31: 3.3 (B6 +4,20) | B31: Hormigón elaborado H21 (fck 210) | C31: m3 | D31: 62 | E31: =H11 -> 60.9 | F31: =D31-E31 -> 1.1 | G31: =IFERROR(F31/E31,0) -> 0.018062397 | H31: 915000 | I31: =D31*H31 -> 56730000 | J31: ='2 Insumos'!F11 -> 0.03 | K31: =IF(ABS(G31)>J31,"ALERTA","OK") -> OK
A32: 3.3 (B6 +4,20) | B32: Acero CA-50 | C32: kg | D32: 7300 | E32: =H12 -> 6960 | F32: =D32-E32 -> 340 | G32: =IFERROR(F32/E32,0) -> 0.048850575 | H32: 9500 | I32: =D32*H32 -> 69350000 | J32: ='2 Insumos'!F12 -> 0.03 | K32: =IF(ABS(G32)>J32,"ALERTA","OK") -> ALERTA

Sheet 7 Costo real mes
A1: Paso 7 · Costo real del mes por ítem
A2: MO: certificado del subcontratista. Directos: remitos. Comunes y equipos: consumo teórico valorizado. El desvío de inventario va aparte (pérdidas).
A4: Ítem | B4: Descripción | C4: Ejecutado | D4: Precio MO subcontrato (Gs/un) | E4: MO certificada (Gs) | F4: Materiales directos (remitos) | G4: Materiales comunes (teórico) | H4: Equipos (teórico) | I4: COSTO REAL (Gs) | J4: Costo real unitario
A5: 3.3 (B3) | B5: Mampostería de elevación ladrillo semiprensado visto ambas caras 0,15 m | C5: ='5 Medición mes'!$G$5 -> 18 | D5: ='2 Insumos'!$D$16 -> 50000 | E5: =C5*D5 -> 900000 | F5: 0 | G5: ='6 Materiales'!E6*'2 Insumos'!$D$6+'6 Materiales'!E7*'2 Insumos'!$D$7+'6 Materiales'!E8*'2 Insumos'!$D$8+'6 Materiales'!E9*'2 Insumos'!$D$9+'6 Materiales'!E10*'2 Insumos'!$D$10 -> 1796580 | H5: 0 | I5: =E5+F5+G5+H5 -> 2696580 | J5: =IFERROR(I5/C5,0) -> 149810
A6: 3.4 (B3) | B6: Mampostería de elevación ladrillo común 0,15 m | C6: ='5 Medición mes'!$G$6 -> 95 | D6: ='2 Insumos'!$D$17 -> 31000 | E6: =C6*D6 -> 2945000 | F6: 0 | G6: ='6 Materiales'!F5*'2 Insumos'!$D$5+'6 Materiales'!F7*'2 Insumos'!$D$7+'6 Materiales'!F8*'2 Insumos'!$D$8+'6 Materiales'!F9*'2 Insumos'!$D$9 -> 5723750 | H6: 0 | I6: =E6+F6+G6+H6 -> 8668750 | J6: =IFERROR(I6/C6,0) -> 91250
A7: 3.2 (B6 +4,20) | B7: Ejecución de losas de HºAº fck 210 kg/cm² | C7: ='5 Medición mes'!$G$7 -> 40 | D7: ='2 Insumos'!$D$18 -> 850000 | E7: =C7*D7 -> 34000000 | F7: ='6 Materiales'!I29+'6 Materiales'!I30 -> 76852500 | G7: ='6 Materiales'!G13*'2 Insumos'!$D$13 -> 900000 | H7: ='6 Materiales'!G14*'2 Insumos'!$D$14+'6 Materiales'!G15*'2 Insumos'!$D$15 -> 13400000 | I7: =E7+F7+G7+H7 -> 125152500 | J7: =IFERROR(I7/C7,0) -> 3128812.5
A8: 3.3 (B6 +4,20) | B8: Ejecución de vigas de HºAº fck 210 kg/cm² | C8: ='5 Medición mes'!$G$8 -> 58 | D8: ='2 Insumos'!$D$19 -> 800000 | E8: =C8*D8 -> 46400000 | F8: ='6 Materiales'!I31+'6 Materiales'!I32 -> 126080000 | G8: ='6 Materiales'!H13*'2 Insumos'!$D$13 -> 1740000 | H8: ='6 Materiales'!H14*'2 Insumos'!$D$14+'6 Materiales'!H15*'2 Insumos'!$D$15 -> 27550000 | I8: =E8+F8+G8+H8 -> 201770000 | J8: =IFERROR(I8/C8,0) -> 3478793.1
B9: Subtotal ítems | E9: =SUM(E5:E8) -> 84245000 | F9: =SUM(F5:F8) -> 202932500 | G9: =SUM(G5:G8) -> 10160330 | H9: =SUM(H5:H8) -> 40950000 | I9: =SUM(I5:I8) -> 338287830
B10: Pérdidas de material (desvío de inventario, no se imputa a ítems) | I10: ='6 Materiales'!$L$25 -> 562670
B11: COSTO REAL TOTAL DEL MES | I11: =I9+I10 -> 338850500

Sheet 8 Resumen
A1: Paso 8 · Venta vs costo vs ejecutado — Mes 3
A2: Todo sin IVA. VG = valor ganado (ejecutado × costo meta). VP = planificado × costo meta. CR = costo real.
A4: Ítem | B4: Descripción | C4: Certificado al cliente sin IVA (Gs) | D4: Valor planificado VP | E4: Valor ganado VG | F4: Costo real CR | G4: Margen real del mes (Gs) | H4: Margen real % | I4: Margen previsto % | J4: Índice costo IC = VG/CR | K4: Índice plazo IP = VG/VP | L4: Costo proyectado al final (Gs) | M4: Resultado proyectado del ítem (Gs) | N4: Diagnóstico
A5: 3.3 (B3) | B5: Mampostería de elevación ladrillo semiprensado visto ambas caras 0,15 m | C5: ='5 Medición mes'!G5*'4 Presupuesto control'!F5 -> 3742655.5 | D5: ='5 Medición mes'!F5*'4 Presupuesto control'!G5 -> 2996200 | E5: ='5 Medición mes'!G5*'4 Presupuesto control'!G5 -> 2696580 | F5: ='7 Costo real mes'!I5 -> 2696580 | G5: =C5-F5 -> 1046075.5 | H5: =IFERROR(G5/C5,0) -> 0.27950088 | I5: ='4 Presupuesto control'!N5 -> 0.27950088 | J5: =IFERROR(E5/F5,0) -> 1 | K5: =IFERROR(E5/D5,0) -> 0.9 | L5: =IFERROR('4 Presupuesto control'!L5/J5,0) -> 7745776.2 | M5: ='4 Presupuesto control'!K5-L5 -> 3004793.8 | N5: =IF(J5<0.95,"Sobrecosto",IF(J5<1,"Leve sobrecosto","Costo OK"))&" · "&IF(K5<0.9,"Atrasado",IF(K5<1,"Leve atraso","En plazo")) -> Costo OK · Leve atraso
A6: 3.4 (B3) | B6: Mampostería de elevación ladrillo común 0,15 m | C6: ='5 Medición mes'!G6*'4 Presupuesto control'!F6 -> 10975992 | D6: ='5 Medición mes'!F6*'4 Presupuesto control'!G6 -> 7300000 | E6: ='5 Medición mes'!G6*'4 Presupuesto control'!G6 -> 8668750 | F6: ='7 Costo real mes'!I6 -> 8668750 | G6: =C6-F6 -> 2307241.7 | H6: =IFERROR(G6/C6,0) -> 0.21020804 | I6: ='4 Presupuesto control'!N6 -> 0.21020804 | J6: =IFERROR(E6/F6,0) -> 1 | K6: =IFERROR(E6/D6,0) -> 1.1875 | L6: =IFERROR('4 Presupuesto control'!L6/J6,0) -> 15823571 | M6: ='4 Presupuesto control'!K6-L6 -> 4211541.8 | N6: =IF(J6<0.95,"Sobrecosto",IF(J6<1,"Leve sobrecosto","Costo OK"))&" · "&IF(K6<0.9,"Atrasado",IF(K6<1,"Leve atraso","En plazo")) -> Costo OK · En plazo
A7: 3.2 (B6 +4,20) | B7: Ejecución de losas de HºAº fck 210 kg/cm² | C7: ='5 Medición mes'!G7*'4 Presupuesto control'!F7 -> 1.2886477e+08 | D7: ='5 Medición mes'!F7*'4 Presupuesto control'!G7 -> 151246875 | E7: ='5 Medición mes'!G7*'4 Presupuesto control'!G7 -> 124100000 | F7: ='7 Costo real mes'!I7 -> 125152500 | G7: =C7-F7 -> 3712266.4 | H7: =IFERROR(G7/C7,0) -> 0.028807458 | I7: ='4 Presupuesto control'!N7 -> 0.036974935 | J7: =IFERROR(E7/F7,0) -> 0.99159026 | K7: =IFERROR(E7/D7,0) -> 0.82051282 | L7: =IFERROR('4 Presupuesto control'!L7/J7,0) -> 3.0505922e+08 | M7: ='4 Presupuesto control'!K7-L7 -> 9048649.3 | N7: =IF(J7<0.95,"Sobrecosto",IF(J7<1,"Leve sobrecosto","Costo OK"))&" · "&IF(K7<0.9,"Atrasado",IF(K7<1,"Leve atraso","En plazo")) -> Leve sobrecosto · Atrasado
A8: 3.3 (B6 +4,20) | B8: Ejecución de vigas de HºAº fck 210 kg/cm² | C8: ='5 Medición mes'!G8*'4 Presupuesto control'!F8 -> 2.0785192e+08 | D8: ='5 Medición mes'!F8*'4 Presupuesto control'!G8 -> 224418000 | E8: ='5 Medición mes'!G8*'4 Presupuesto control'!G8 -> 196620000 | F8: ='7 Costo real mes'!I8 -> 201770000 | G8: =C8-F8 -> 6081921 | H8: =IFERROR(G8/C8,0) -> 0.029260836 | I8: ='4 Presupuesto control'!N8 -> 0.054038091 | J8: =IFERROR(E8/F8,0) -> 0.97447589 | K8: =IFERROR(E8/D8,0) -> 0.87613293 | L8: =IFERROR('4 Presupuesto control'!L8/J8,0) -> 4.6059221e+08 | M8: ='4 Presupuesto control'!K8-L8 -> 13883558 | N8: =IF(J8<0.95,"Sobrecosto",IF(J8<1,"Leve sobrecosto","Costo OK"))&" · "&IF(K8<0.9,"Atrasado",IF(K8<1,"Leve atraso","En plazo")) -> Leve sobrecosto · Atrasado
B9: Subtotal ítems | C9: =SUM(C5:C8) -> 3.5143533e+08 | D9: =SUM(D5:D8) -> 385961075 | E9: =SUM(E5:E8) -> 332085330 | F9: =SUM(F5:F8) -> 338287830 | G9: =SUM(G5:G8) -> 13147505 | H9: =IFERROR(G9/C9,0) -> 0.037410878 | J9: =IFERROR(E9/F9,0) -> 0.98166502 | K9: =IFERROR(E9/D9,0) -> 0.86041145 | L9: =SUM(L5:L8) -> 7.8922077e+08 | M9: =SUM(M5:M8) -> 30148542
B10: Pérdidas de material del mes | F10: ='7 Costo real mes'!I10 -> 562670 | G10: =-F10 -> -562670
B11: RESULTADO DEL MES | C11: =C9 -> 3.5143533e+08 | F11: =F9+F10 -> 338850500 | G11: =C11-F11 -> 12584835 | H11: =IFERROR(G11/C11,0) -> 0.035809816
A13: Cómo leerlo:
A14: • Certificado − Costo real = lo que realmente ganaste este mes en cada ítem.
A15: • IC < 1: cada Gs de trabajo hecho te costó más de lo presupuestado. IP < 1: hiciste menos de lo planificado.
A16: • Costo proyectado = costo meta total ÷ IC: si el ítem sigue igual, cuánto te va a costar terminarlo.
A17: • Las pérdidas de material se muestran aparte: no ensucian el costo de los ítems, pero sí bajan el resultado de la obra.
